Workbook

Sheet Mode d'emploi
A1: Modèle de planning des bénévoles
A2: Ce modèle répartit vos bénévoles sur une semaine : un bloc par poste, une colonne par jour, le nombre de personnes voulu pour chaque créneau, les noms des inscrits, et ce qui manque encore, en chiffres et en couleur.
A4: Remplir le planning
A5: 1. Dans l'onglet « Planning », écrivez le nom de l'événement en B2 et la date du premier jour en B3 (par exemple 14/06/2027). Les en-têtes des jours se mettent à jour.
A6: 2. Remplacez les postes d'exemple (Accueil, Buvette, Montage et rangement) par les vôtres : le nom du poste s'écrit sur la ligne colorée du bloc, les lignes en dessous le reprennent.
A7: 3. Pour chaque créneau, écrivez son horaire dans la colonne B, sur la ligne « Besoin ».
A8: 4. Sur la ligne « Besoin », indiquez pour chaque jour le nombre de personnes voulu. Laissez la case vide si le créneau n'a pas lieu ce jour-là.
A9: 5. Écrivez un nom par case sur les lignes « Nom 1 » à « Nom 6 ». « Inscrits » et « Manque » se calculent seuls.
A10: 6. L'onglet « Récapitulatif » additionne le besoin, les inscrits et le manque par jour, et le manque par poste.
A12: Lire les couleurs
A13: Ligne « Manque » en rouge : il manque encore des personnes sur ce créneau, ce jour-là. Le chiffre dit combien.
A14: Ligne « Manque » en vert : le créneau a le nombre de personnes voulu.
... A28: Modèle proposé par benevol.app : https://www.benevol.app/modele-planning-benevoles

Sheet Planning
A1: Planning des bénévoles
A2: Événement | B2: Fête d'été (exemple)
A3: Premier jour
A5: Poste | B5: Créneau | C5: Ligne | D5: =IF($B$3="","Jour 1",CHOOSE(WEEKDAY($B$3,2),"lundi","mardi","mercredi","jeudi","vendredi","samedi","dimanche")&" "&RIGHT("0"&DAY($B$3),2)&"/"&RIGHT("0"&MONTH($B$3),2)) | E5: =IF($B$3="","Jour 2",CHOOSE(WEEKDAY(($B$3+1),2),"lundi","mardi","mercredi","jeudi","vendredi","samedi","dimanche")&" "&RIGHT("0"&DAY(($B$3+1)),2)&"/"&RIGHT("0"&MONTH(($B$3+1)),2)) | F5: =IF($B$3="","Jour 3",CHOOSE(WEEKDAY(($B$3+2),2),"lundi","mardi","mercredi","jeudi","vendredi","samedi","dimanche")&" "&RIGHT("0"&DAY(($B$3+2)),2)&"/"&RIGHT("0"&MONTH(($B$3+2)),2)) | G5: =IF($B$3="","Jour 4",CHOOSE(WEEKDAY(($B$3+3),2),"lundi","mardi","mercredi","jeudi","vendredi","samedi","dimanche")&" "&RIGHT("0"&DAY(($B$3+3)),2)&"/"&RIGHT("0"&MONTH(($B$3+3)),2)) | H5: =IF($B$3="","Jour 5",CHOOSE(WEEKDAY(($B$3+4),2),"lundi","mardi","mercredi","jeudi","vendredi","samedi","dimanche")&" "&RIGHT("0"&DAY(($B$3+4)),2)&"/"&RIGHT("0"&MONTH(($B$3+4)),2)) | I5: =IF($B$3="","Jour 6",CHOOSE(WEEKDAY(($B$3+5),2),"lundi","mardi","mercredi","jeudi","vendredi","samedi","dimanche")&" "&RIGHT("0"&DAY(($B$3+5)),2)&"/"&RIGHT("0"&MONTH(($B$3+5)),2)) | J5: =IF($B$3="","Jour 7",CHOOSE(WEEKDAY(($B$3+6),2),"lundi","mardi","mercredi","jeudi","vendredi","samedi","dimanche")&" "&RIGHT("0"&DAY(($B$3+6)),2)&"/"&RIGHT("0"&MONTH(($B$3+6)),2))
A6: Accueil
A7: =A6 | B7: 9 h à 12 h | C7: Besoin | D7: 2 | E7: 2 | F7: 2 | G7: 2 | H7: 2 | I7: 3 | J7: 3
A8: =A7 | B8: =B7 | C8: Nom 1
A9: =A8 | B9: =B8 | C9: Nom 2
A10: =A9 | B10: =B9 | C10: Nom 3
A11: =A10 | B11: =B10 | C11: Nom 4
A12: =A11 | B12: =B11 | C12: Nom 5
A13: =A12 | B13: =B12 | C13: Nom 6
A14: =A13 | B14: =B13 | C14: Inscrits | D14: =COUNTA(D8:D13) | E14: =COUNTA(E8:E13) | F14: =COUNTA(F8:F13) | G14: =COUNTA(G8:G13) | H14: =COUNTA(H8:H13) | I14: =COUNTA(I8:I13) | J14: =COUNTA(J8:J13)
A15: =A14 | B15: =B14 | C15: Manque | D15: =IF(D7="","",MAX(0,D7-D14)) | E15: =IF(E7="","",MAX(0,E7-E14)) | F15: =IF(F7="","",MAX(0,F7-F14)) | G15: =IF(G7="","",MAX(0,G7-G14)) | H15: =IF(H7="","",MAX(0,H7-H14)) | I15: =IF(I7="","",MAX(0,I7-I14)) | J15: =IF(J7="","",MAX(0,J7-J14))
A16: =A15 | B16: 14 h à 18 h | C16: Besoin | D16: 2 | E16: 2 | F16: 2 | G16: 2 | H16: 2 | I16: 3 | J16: 3
A17: =A16 | B17: =B16 | C17: Nom 1
A18: =A17 | B18: =B17 | C18: Nom 2
A19: =A18 | B19: =B18 | C19: Nom 3
A20: =A19 | B20: =B19 | C20: Nom 4
A21: =A20 | B21: =B20 | C21: Nom 5
A22: =A21 | B22: =B21 | C22: Nom 6
A23: =A22 | B23: =B22 | C23: Inscrits | D23: =COUNTA(D17:D22) | E23: =COUNTA(E17:E22) | F23: =COUNTA(F17:F22) | G23: =COUNTA(G17:G22) | H23: =COUNTA(H17:H22) | I23: =COUNTA(I17:I22) | J23: =COUNTA(J17:J22)
A24: =A23 | B24: =B23 | C24: Manque | D24: =IF(D16="","",MAX(0,D16-D23)) | E24: =IF(E16="","",MAX(0,E16-E23)) | F24: =IF(F16="","",MAX(0,F16-F23)) | G24: =IF(G16="","",MAX(0,G16-G23)) | H24: =IF(H16="","",MAX(0,H16-H23)) | I24: =IF(I16="","",MAX(0,I16-I23)) | J24: =IF(J16="","",MAX(0,J16-J23))
A26: Buvette
A27: =A26 | B27: 11 h à 15 h | C27: Besoin | H27: 3 | I27: 4 | J27: 4
A28: =A27 | B28: =B27 | C28: Nom 1
A29: =A28 | B29: =B28 | C29: Nom 2
A30: =A29 | B30: =B29 | C30: Nom 3
A31: =A30 | B31: =B30 | C31: Nom 4
A32: =A31 | B32: =B31 | C32: Nom 5
A33: =A32 | B33: =B32 | C33: Nom 6
A34: =A33 | B34: =B33 | C34: Inscrits | D34: =COUNTA(D28:D33) | E34: =COUNTA(E28:E33) | F34: =COUNTA(F28:F33) | G34: =COUNTA(G28:G33) | H34: =COUNTA(H28:H33) | I34: =COUNTA(I28:I33) | J34: =COUNTA(J28:J33)
A35: =A34 | B35: =B34 | C35: Manque | D35: =IF(D27="","",MAX(0,D27-D34)) | E35: =IF(E27="","",MAX(0,E27-E34)) | F35: =IF(F27="","",MAX(0,F27-F34)) | G35: =IF(G27="","",MAX(0,G27-G34)) | H35: =IF(H27="","",MAX(0,H27-H34)) | I35: =IF(I27="","",MAX(0,I27-I34)) | J35: =IF(J27="","",MAX(0,J27-J34))
A36: =A35 | B36: 18 h à 23 h | C36: Besoin | H36: 4 | I36: 4
A37: =A36 | B37: =B36 | C37: Nom 1
A38: =A37 | B38: =B37 | C38: Nom 2
A39: =A38 | B39: =B38 | C39: Nom 3
A40: =A39 | B40: =B39 | C40: Nom 4
A41: =A40 | B41: =B40 | C41: Nom 5
A42: =A41 | B42: =B41 | C42: Nom 6
...

Sheet Récapitulatif
A1: Récapitulatif de la semaine
A3: Par jour | B3: ='Planning'!D5 | C3: ='Planning'!E5 | D3: ='Planning'!F5 | E3: ='Planning'!G5 | F3: ='Planning'!H5 | G3: ='Planning'!I5 | H3: ='Planning'!J5 | I3: Semaine
A4: Besoin | B4: =SUMIF('Planning'!$C:$C,"Besoin",'Planning'!D:D) | C4: =SUMIF('Planning'!$C:$C,"Besoin",'Planning'!E:E) | D4: =SUMIF('Planning'!$C:$C,"Besoin",'Planning'!F:F) | E4: =SUMIF('Planning'!$C:$C,"Besoin",'Planning'!G:G) | F4: =SUMIF('Planning'!$C:$C,"Besoin",'Planning'!H:H) | G4: =SUMIF('Planning'!$C:$C,"Besoin",'Planning'!I:I) | H4: =SUMIF('Planning'!$C:$C,"Besoin",'Planning'!J:J) | I4: =SUM(B4:H4)
A5: Inscrits | B5: =SUMIF('Planning'!$C:$C,"Inscrits",'Planning'!D:D) | C5: =SUMIF('Planning'!$C:$C,"Inscrits",'Planning'!E:E) | D5: =SUMIF('Planning'!$C:$C,"Inscrits",'Planning'!F:F) | E5: =SUMIF('Planning'!$C:$C,"Inscrits",'Planning'!G:G) | F5: =SUMIF('Planning'!$C:$C,"Inscrits",'Planning'!H:H) | G5: =SUMIF('Planning'!$C:$C,"Inscrits",'Planning'!I:I) | H5: =SUMIF('Planning'!$C:$C,"Inscrits",'Planning'!J:J) | I5: =SUM(B5:H5)
A6: Manque | B6: =SUMIF('Planning'!$C:$C,"Manque",'Planning'!D:D) | C6: =SUMIF('Planning'!$C:$C,"Manque",'Planning'!E:E) | D6: =SUMIF('Planning'!$C:$C,"Manque",'Planning'!F:F) | E6: =SUMIF('Planning'!$C:$C,"Manque",'Planning'!G:G) | F6: =SUMIF('Planning'!$C:$C,"Manque",'Planning'!H:H) | G6: =SUMIF('Planning'!$C:$C,"Manque",'Planning'!I:I) | H6: =SUMIF('Planning'!$C:$C,"Manque",'Planning'!J:J) | I6: =SUM(B6:H6)
A9: Manque par poste | B9: ='Planning'!D5 | C9: ='Planning'!E5 | D9: ='Planning'!F5 | E9: ='Planning'!G5 | F9: ='Planning'!H5 | G9: ='Planning'!I5 | H9: ='Planning'!J5 | I9: Semaine
A10: ='Planning'!A6 | B10: =SUMIFS('Planning'!D:D,'Planning'!$A:$A,$A10,'Planning'!$C:$C,"Manque") | C10: =SUMIFS('Planning'!E:E,'Planning'!$A:$A,$A10,'Planning'!$C:$C,"Manque") | D10: =SUMIFS('Planning'!F:F,'Planning'!$A:$A,$A10,'Planning'!$C:$C,"Manque") | E10: =SUMIFS('Planning'!G:G,'Planning'!$A:$A,$A10,'Planning'!$C:$C,"Manque") | F10: =SUMIFS('Planning'!H:H,'Planning'!$A:$A,$A10,'Planning'!$C:$C,"Manque") | G10: =SUMIFS('Planning'!I:I,'Planning'!$A:$A,$A10,'Planning'!$C:$C,"Manque") | H10: =SUMIFS('Planning'!J:J,'Planning'!$A:$A,$A10,'Planning'!$C:$C,"Manque") | I10: =SUM(B10:H10)
A11: ='Planning'!A26 | B11: =SUMIFS('Planning'!D:D,'Planning'!$A:$A,$A11,'Planning'!$C:$C,"Manque") | C11: =SUMIFS('Planning'!E:E,'Planning'!$A:$A,$A11,'Planning'!$C:$C,"Manque") | D11: =SUMIFS('Planning'!F:F,'Planning'!$A:$A,$A11,'Planning'!$C:$C,"Manque") | E11: =SUMIFS('Planning'!G:G,'Planning'!$A:$A,$A11,'Planning'!$C:$C,"Manque") | F11: =SUMIFS('Planning'!H:H,'Planning'!$A:$A,$A11,'Planning'!$C:$C,"Manque") | G11: =SUMIFS('Planning'!I:I,'Planning'!$A:$A,$A11,'Planning'!$C:$C,"Manque") | H11: =SUMIFS('Planning'!J:J,'Planning'!$A:$A,$A11,'Planning'!$C:$C,"Manque") | I11: =SUM(B11:H11)
A12: ='Planning'!A46 | B12: =SUMIFS('Planning'!D:D,'Planning'!$A:$A,$A12,'Planning'!$C:$C,"Manque") | C12: =SUMIFS('Planning'!E:E,'Planning'!$A:$A,$A12,'Planning'!$C:$C,"Manque") | D12: =SUMIFS('Planning'!F:F,'Planning'!$A:$A,$A12,'Planning'!$C:$C,"Manque") | E12: =SUMIFS('Planning'!G:G,'Planning'!$A:$A,$A12,'Planning'!$C:$C,"Manque") | F12: =SUMIFS('Planning'!H:H,'Planning'!$A:$A,$A12,'Planning'!$C:$C,"Manque") | G12: =SUMIFS('Planning'!I:I,'Planning'!$A:$A,$A12,'Planning'!$C:$C,"Manque") | H12: =SUMIFS('Planning'!J:J,'Planning'!$A:$A,$A12,'Planning'!$C:$C,"Manque") | I12: =SUM(B12:H12)
